Traceback (most recent call last):
  File "/opt/homebrew/Caskroom/miniconda/base/envs/ct-book/lib/python3.11/site-packages/jupyter_cache/executors/utils.py", line 58, in single_nb_execution
    executenb(
  File "/opt/homebrew/Caskroom/miniconda/base/envs/ct-book/lib/python3.11/site-packages/nbclient/client.py", line 1305, in execute
    return NotebookClient(nb=nb, resources=resources, km=km, **kwargs).execute()
           ^^^^^^^^^^^^^^^^^^^^^^^^^^^^^^^^^^^^^^^^^^^^^^^^^^^^^^^^^^^^^^^^^^^^^
  File "/opt/homebrew/Caskroom/miniconda/base/envs/ct-book/lib/python3.11/site-packages/jupyter_core/utils/__init__.py", line 166, in wrapped
    return loop.run_until_complete(inner)
           ^^^^^^^^^^^^^^^^^^^^^^^^^^^^^^
  File "/opt/homebrew/Caskroom/miniconda/base/envs/ct-book/lib/python3.11/asyncio/base_events.py", line 653, in run_until_complete
    return future.result()
           ^^^^^^^^^^^^^^^
  File "/opt/homebrew/Caskroom/miniconda/base/envs/ct-book/lib/python3.11/site-packages/nbclient/client.py", line 705, in async_execute
    await self.async_execute_cell(
  File "/opt/homebrew/Caskroom/miniconda/base/envs/ct-book/lib/python3.11/site-packages/nbclient/client.py", line 1058, in async_execute_cell
    await self._check_raise_for_error(cell, cell_index, exec_reply)
  File "/opt/homebrew/Caskroom/miniconda/base/envs/ct-book/lib/python3.11/site-packages/nbclient/client.py", line 914, in _check_raise_for_error
    raise CellExecutionError.from_cell_and_msg(cell, exec_reply_content)
nbclient.exceptions.CellExecutionError: An error occurred while executing the following cell:
------------------
quiz=[{
    "question": "Nennen Sie Ihre Antwort:",
    "type": "numeric",
    "precision": 2,
    "answers": [
        {
            "type": "value",
            "value": 0.05,
            "correct": True,
            "feedback": "Richtig."
        }
    ]
}]

from jupyterquiz import display_quiz
display_quiz(quiz, border_radius=2, lang='de')
------------------


[0;31m---------------------------------------------------------------------------[0m
[0;31mTypeError[0m                                 Traceback (most recent call last)
Cell [0;32mIn[1], line 16[0m
[1;32m      1[0m quiz[38;5;241m=[39m[{
[1;32m      2[0m     [38;5;124m"[39m[38;5;124mquestion[39m[38;5;124m"[39m: [38;5;124m"[39m[38;5;124mNennen Sie Ihre Antwort:[39m[38;5;124m"[39m,
[1;32m      3[0m     [38;5;124m"[39m[38;5;124mtype[39m[38;5;124m"[39m: [38;5;124m"[39m[38;5;124mnumeric[39m[38;5;124m"[39m,
[0;32m   (...)[0m
[1;32m     12[0m     ]
[1;32m     13[0m }]
[1;32m     15[0m [38;5;28;01mfrom[39;00m [38;5;21;01mjupyterquiz[39;00m [38;5;28;01mimport[39;00m display_quiz
[0;32m---> 16[0m [43mdisplay_quiz[49m[43m([49m[43mquiz[49m[43m,[49m[43m [49m[43mborder_radius[49m[38;5;241;43m=[39;49m[38;5;241;43m2[39;49m[43m,[49m[43m [49m[43mlang[49m[38;5;241;43m=[39;49m[38;5;124;43m'[39;49m[38;5;124;43mde[39;49m[38;5;124;43m'[39;49m[43m)[49m

[0;31mTypeError[0m: display_quiz() got an unexpected keyword argument 'lang'

