Traceback (most recent call last):
  File "/Users/bzoennchen/Development/workspaces/python3env/lib/python3.9/site-packages/jupyter_cache/executors/utils.py", line 51, in single_nb_execution
    executenb(
  File "/Users/bzoennchen/Development/workspaces/python3env/lib/python3.9/site-packages/nbclient/client.py", line 1107, in execute
    return NotebookClient(nb=nb, resources=resources, km=km, **kwargs).execute()
  File "/Users/bzoennchen/Development/workspaces/python3env/lib/python3.9/site-packages/nbclient/util.py", line 74, in wrapped
    return just_run(coro(*args, **kwargs))
  File "/Users/bzoennchen/Development/workspaces/python3env/lib/python3.9/site-packages/nbclient/util.py", line 53, in just_run
    return loop.run_until_complete(coro)
  File "/usr/local/Cellar/python@3.9/3.9.6/Frameworks/Python.framework/Versions/3.9/lib/python3.9/asyncio/base_events.py", line 642, in run_until_complete
    return future.result()
  File "/Users/bzoennchen/Development/workspaces/python3env/lib/python3.9/site-packages/nbclient/client.py", line 553, in async_execute
    await self.async_execute_cell(
  File "/Users/bzoennchen/Development/workspaces/python3env/lib/python3.9/site-packages/nbclient/client.py", line 852, in async_execute_cell
    self._check_raise_for_error(cell, exec_reply)
  File "/Users/bzoennchen/Development/workspaces/python3env/lib/python3.9/site-packages/nbclient/client.py", line 760, in _check_raise_for_error
    raise CellExecutionError.from_cell_and_msg(cell, exec_reply_content)
nbclient.exceptions.CellExecutionError: An error occurred while executing the following cell:
------------------
def experiment(nrows, ncols):
    world = rw.new_world(nrows=nrows, ncols=ncols)
    world.disable_animation()
    robo = world.get_robo()
    robo.disable_print()
    return random_walk(robo)

def experiments(nrows, ncols, n):
    mean = 0
    for _ in range(n):
        mean += experiment(nrows, ncols)
    return mean / n

mean = experiments(nrows=7, ncols=7, n=50)
print(mean)
------------------

[0;31m---------------------------------------------------------------------------[0m
[0;31mTypeError[0m                                 Traceback (most recent call last)
[0;32m<ipython-input-27-2b1c14174a66>[0m in [0;36m<module>[0;34m[0m
[1;32m     12[0m     [0;32mreturn[0m [0mmean[0m [0;34m/[0m [0mn[0m[0;34m[0m[0;34m[0m[0m
[1;32m     13[0m [0;34m[0m[0m
[0;32m---> 14[0;31m [0mmean[0m [0;34m=[0m [0mexperiments[0m[0;34m([0m[0mnrows[0m[0;34m=[0m[0;36m7[0m[0;34m,[0m [0mncols[0m[0;34m=[0m[0;36m7[0m[0;34m,[0m [0mn[0m[0;34m=[0m[0;36m50[0m[0;34m)[0m[0;34m[0m[0;34m[0m[0m
[0m[1;32m     15[0m [0mprint[0m[0;34m([0m[0mmean[0m[0;34m)[0m[0;34m[0m[0;34m[0m[0m

[0;32m<ipython-input-27-2b1c14174a66>[0m in [0;36mexperiments[0;34m(nrows, ncols, n)[0m
[1;32m      9[0m     [0mmean[0m [0;34m=[0m [0;36m0[0m[0;34m[0m[0;34m[0m[0m
[1;32m     10[0m     [0;32mfor[0m [0m_[0m [0;32min[0m [0mrange[0m[0;34m([0m[0mn[0m[0;34m)[0m[0;34m:[0m[0;34m[0m[0;34m[0m[0m
[0;32m---> 11[0;31m         [0mmean[0m [0;34m+=[0m [0mexperiment[0m[0;34m([0m[0mnrows[0m[0;34m,[0m [0mncols[0m[0;34m)[0m[0;34m[0m[0;34m[0m[0m
[0m[1;32m     12[0m     [0;32mreturn[0m [0mmean[0m [0;34m/[0m [0mn[0m[0;34m[0m[0;34m[0m[0m
[1;32m     13[0m [0;34m[0m[0m

[0;31mTypeError[0m: unsupported operand type(s) for +=: 'int' and 'NoneType'
TypeError: unsupported operand type(s) for +=: 'int' and 'NoneType'

